Workbook
Name TypeLabels: OFFSET('1. Guide & Labels'!$B$21,0,0,COUNTA('1. Guide & Labels'!$B$21:$B$31),1)
Name StreamLabels: OFFSET('1. Guide & Labels'!$B$34,0,0,COUNTA('1. Guide & Labels'!$B$34:$B$47),1)

Sheet 1. Guide & Labels
B1: Indian Liberals — Organisation Classification
B2: Every organisation on indianliberals.in with its current classification. Snapshot of 24 July 2026, prepared by Adnan.
B4: AT A GLANCE
B5: Organisations in this file | C5: =COUNTA('2. Organisations'!$A$2:$A$5000)
B6: Shown on the /organisations/ page | C6: =COUNTIF('2. Organisations'!$G:$G,"Yes")
B7: Still flagged for review (Notes empty) | C7: =COUNTA('2. Organisations'!$A$2:$A$5000)-COUNTA('2. Organisations'!$H$2:$H$5000)
B9: HOW TO USE
B10: • All classification happens on the '2. Organisations' tab — one row per organisation, nobody left out.
B11: • Work with the dropdowns: Type is the main classification; the two Stream columns are optional tags for the liberal current(s) an organisation belongs to.
B12: • The dropdown options come from the label tables below. Type a new label into an empty slot (top-down, no gaps) and it appears in the dropdowns immediately.
B13: • 'On organisations page?' controls the public /organisations/ index. Set Yes to list it, No to keep the record but hide it from the index. Nothing is ever deleted from the site.
B14: • Please read and correct the Description — these were AI-drafted and need an editorial eye.
B15: • Missing an organisation? Add a row at the bottom — name plus type is enough. Leave the ID column blank; we generate those.
B16: • Anything the dropdowns can't express (dates, spellings, mergers, disagreements) goes in 'Notes / corrections'.
B17: • Sorting and filtering are safe — every row carries its ID in the last column. Just don't edit or clear the ID column itself.
B18: • Colours are decorative. New labels you add won't be coloured — that's fine.
B19: TYPE | C19: the main classification — feeds the Type dropdown on the Organisations sheet
B20: Label | C20: What it means | D20: Orgs right now
B21: Political Party | C21: A party that contested elections within the liberal / constitutional tradition. | D21: =IF($B21="","",COUNTIF('2. Organisations'!$C:$C,$B21))
B22: Think Tank | C22: Policy research and advocacy institutes advancing liberal ideas. | D22: =IF($B22="","",COUNTIF('2. Organisations'!$C:$C,$B22))
B23: Publisher / Press | C23: Publishing houses, trusts and presses that carried liberal writing. | D23: =IF($B23="","",COUNTIF('2. Organisations'!$C:$C,$B23))
B24: Reform Society | C24: Nineteenth / early-twentieth-century social-reform associations. | D24: =IF($B24="","",COUNTIF('2. Organisations'!$C:$C,$B24))
B25: Professional Body | C25: Chambers, editors' conferences, trade and professional associations. | D25: =IF($B25="","",COUNTIF('2. Organisations'!$C:$C,$B25))
B26: Academic Institution | C26: Colleges, institutes and learned societies in the archive. | D26: =IF($B26="","",COUNTIF('2. Organisations'!$C:$C,$B26))
B27: International Network | C27: Global liberal / free-market networks India connected to. | D27: =IF($B27="","",COUNTIF('2. Organisations'!$C:$C,$B27))
C28: ← add new types here — fill top-down, no gaps; they appear in the dropdown automatically | D28: =IF($B28="","",COUNTIF('2. Organisations'!$C:$C,$B28))
D29: =IF($B29="","",COUNTIF('2. Organisations'!$C:$C,$B29))
D30: =IF($B30="","",COUNTIF('2. Organisations'!$C:$C,$B30))
D31: =IF($B31="","",COUNTIF('2. Organisations'!$C:$C,$B31))
B32: LIBERAL STREAM | C32: optional tags — feed the Stream 1 & Stream 2 dropdowns
B33: Label | C33: What it means | D33: Orgs right now
B34: Classical Liberal | C34: Individual liberty, free markets, limited government. | D34: =IF($B34="","",COUNTIF('2. Organisations'!$D:$E,$B34))
B35: Libertarian | C35: The explicitly libertarian stream. | D35: =IF($B35="","",COUNTIF('2. Organisations'!$D:$E,$B35))
B36: Free Enterprise | C36: Pro-market, pro-business enterprise advocacy. | D36: =IF($B36="","",COUNTIF('2. Organisations'!$D:$E,$B36))
B37: Constitutionalist | C37: Rule of law and liberal constitutional order. | D37: =IF($B37="","",COUNTIF('2. Organisations'!$D:$E,$B37))
B38: Civil Libertarian | C38: Civil liberties and individual rights against the state. | D38: =IF($B38="","",COUNTIF('2. Organisations'!$D:$E,$B38))
B39: Individual Rights | C39: Rights of the individual as the organising principle. | D39: =IF($B39="","",COUNTIF('2. Organisations'!$D:$E,$B39))
B40: Reformist | C40: Social-reform orientation (caste, education, custom). | D40: =IF($B40="","",COUNTIF('2. Organisations'!$D:$E,$B40))
B41: Humanist | C41: Rationalist / humanist current. | D41: =IF($B41="","",COUNTIF('2. Organisations'!$D:$E,$B41))
B42: Agrarian Reform | C42: Farmer / land / agrarian liberalisation. | D42: =IF($B42="","",COUNTIF('2. Organisations'!$D:$E,$B42))
...

Sheet 2. Organisations
A1: Organisation | B1: Lifespan | C1: Type | D1: Stream 1 | E1: Stream 2 (optional) | F1: Description (please correct) | G1: On organisations page? | H1: Notes / corrections | I1: Also known as | J1: Has logo | K1: ID (don't edit)
A2: A. D. Shroff Memorial Trust | C2: Publisher / Press | F2: Mumbai trust that publishes lectures and pamphlets honouring A. D. Shroff, co-founder of the Forum of Free Enterprise. | G2: Yes | J2: No | K2: a-d-shroff-memorial-trust
A3: Academic Association (Derozio) | B3: 1828–1831 | C3: Academic Institution | D3: Reformist | F3: The Calcutta student debating society founded by Henry Derozio at Hindu College — seedbed of the Young Bengal movement and of early Indian free thought. | G3: Yes | J3: No | K3: academic-association-derozio
A4: All-India Liberal Federation | C4: Political Party | D4: Classical Liberal | F4: The organised home of India's moderate liberals after their 1918 parting with Congress, carrying the Gokhale tradition into the era of legislatures and dyarchy. | G4: No | J4: No | K4: all-india-liberal-federation
A5: All-India Newspaper Editors Conference | B5: founded 1940 | C5: Professional Body | F5: Representative body of Indian newspaper editors, founded in 1940 to defend press freedom and editorial independence. | G5: Yes | J5: No | K5: all-india-newspaper-editors-conference
A6: All-India Sarafa Association | C6: Professional Body | F6: Trade association of India's bullion and silver merchants, a vocal critic of the gold-control orders of the 1960s. | G6: Yes | J6: No | K6: all-india-sarafa-association
A7: Atlas Network | C7: International Network | D7: Classical Liberal | F7: US-based network that incubates and connects free-market think tanks worldwide, including several Indian institutes. | G7: Yes | J7: Yes | K7: atlas-network
A8: Bharathan Publications | C8: Publisher / Press | D8: Classical Liberal | F8: Madras publishing house associated with Swatantra-era liberal writing, including works of C. Rajagopalachari's circle. | G8: Yes | J8: No | K8: bharathan-publications
A9: Bharatiya Vidya Bhavan | B9: founded 1938 | C9: Academic Institution | F9: Educational trust founded by K. M. Munshi in 1938 to promote Indian culture and letters; publisher of several works in this archive. | G9: Yes | J9: Yes | K9: bharatiya-vidya-bhavan
A10: Bombay Stock Exchange | B10: founded 1875 | C10: Professional Body | F10: Asia's oldest stock exchange, founded in 1875 — the institutional heart of Indian equity capitalism. | G10: Yes | J10: Yes | K10: bombay-stock-exchange
A11: Brahmo Samaj | B11: founded 1828 | C11: Reform Society | D11: Constitutionalist | E11: Reformist | F11: The reform movement founded by Raja Ram Mohan Roy in 1828, which led the nineteenth-century campaigns against sati and orthodoxy and for widow remarriage and women's education. | G11: Yes | J11: No | K11: brahmo-samaj
A12: Centre for Civil Society | B12: founded 1997 | C12: Think Tank | D12: Classical Liberal | F12: New Delhi think tank founded by Parth J. Shah in 1997, advancing choice and accountability in education, livelihoods, and governance — and the custodian of this archive. | G12: Yes | J12: Yes | K12: centre-for-civil-society
A13: Congress Socialist Party | B13: 1934–1948 | C13: Political Party | F13: The socialist caucus within the Indian National Congress (1934–1948); several of its members, Minoo Masani among them, later travelled to market liberalism. | G13: No | J13: No | K13: congress-socialist-party
A14: Council for Liberal Democracy | B14: founded 1981 | C14: Think Tank | D14: Classical Liberal | F14: Forum founded in 1981 around Minoo Masani to keep liberal democratic ideas alive in Indian public debate through the late License Raj years. | G14: Yes | J14: No | K14: council-for-liberal-democracy
A15: Council of Asian Liberals and Democrats | B15: founded 1993 | C15: International Network | D15: Classical Liberal | F15: Network of liberal and democratic political parties across Asia, founded in 1993. | G15: Yes | J15: Yes | K15: council-of-asian-liberals-and-democrats
A16: Federation of Indian Chambers of Commerce | B16: founded 1927 | C16: Professional Body | F16: FICCI — the apex chamber of Indian business, founded in 1927 by G. D. Birla and Purshottamdas Thakurdas. | G16: Yes | J16: Yes | K16: federation-of-indian-chambers-of-commerce
A17: Ford Foundation | B17: founded 1936 | C17: International Network | F17: American philanthropic foundation whose grants shaped Indian planning, agriculture, and social-science research from the 1950s onward. | G17: Yes | J17: Yes | K17: ford-foundation
A18: Forum of Free Enterprise | B18: founded 1956 | C18: Think Tank | D18: Classical Liberal | E18: Free Enterprise | F18: Mumbai educational organisation founded by A. D. Shroff in 1956 to make the public case for free enterprise; its lectures and pamphlets form one of the largest runs in this archive. | G18: Yes | I18: FFE; The Forum | J18: No | K18: forum-of-free-enterprise
A19: Friedrich Naumann Foundation for Freedom | B19: founded 1958 | C19: International Network | D19: Classical Liberal | F19: The German liberal political foundation, founded in 1958, a long-standing partner to liberal institutions across South Asia. | G19: Yes | J19: Yes | K19: friedrich-naumann-foundation
A20: Hindu College Calcutta | B20: founded 1817 | C20: Academic Institution | F20: Founded in 1817, the first major modern educational institution in India and a crucible of the Bengal Renaissance. | G20: Yes | J20: No | K20: hindu-college-calcutta
A21: Hoover Institution | B21: founded 1919 | C21: Academic Institution | D21: Classical Liberal | F21: Stanford-based research institution on war, revolution, and peace; an intellectual home to several of the free-market economists in this archive. | G21: Yes | J21: Yes | K21: hoover-institution
A22: Indian Liberal Group | B22: founded 2000 | C22: Think Tank | D22: Classical Liberal | F22: A discussion circle of contemporary Indian liberals continuing the Masani-era liberal conversation. | G22: Yes | J22: No | K22: indian-liberal-group
A23: Indian Merchants Chamber | B23: founded 1907 | C23: Professional Body | F23: Bombay chamber of Indian business founded in 1907 — a platform first for swadeshi enterprise and later for market liberalism. | G23: Yes | J23: Yes | K23: indian-merchants-chamber
A24: Indian National Congress | B24: founded 1885 | C24: Political Party | F24: The party of the freedom movement, founded in 1885. The early moderates who built Indian liberalism worked within it; the post-independence liberals defined themselves against its planned economy. | G24: No | J24: No | K24: indian-national-congress
A25: Initiative for Open Society | C25: Publisher / Press | D25: Classical Liberal | F25: 'Pahel' — the Vadodara initiative that published Khoj, the Gujarati liberal periodical anchored in Popper and Hayek. | G25: Yes | J25: No | K25: initiative-for-open-society
A26: Janashakti Books and Publications | C26: Publisher / Press | D26: Classical Liberal | E26: Agrarian Reform | F26: Marathi publisher associated with the farmers'-movement literature in this archive. | G26: Yes | J26: No | K26: janashakti-books-and-publications
A27: Janashakti Vachak Chalval | C27: Reform Society | D27: Classical Liberal | E27: Agrarian Reform | F27: Marathi readers' movement that circulated farmers'-movement and liberal writing across Maharashtra. | G27: Yes | J27: No | K27: janashakti-vachak-chalval
A28: John Templeton Foundation | B28: founded 1987 | C28: International Network | F28: US foundation funding research at the intersection of markets, character, and human flourishing. | G28: Yes | J28: Yes | K28: john-templeton-foundation
A29: Kisan Samvay Samiti | C29: Reform Society | D29: Agrarian Reform | F29: Farmers' coordination body in the orbit of the Shetkari Sanghatana movement. | G29: Yes | J29: No | K29: kisan-samvay-samiti
A30: Leslie Sawhny Centre | C30: Academic Institution | D30: Classical Liberal | F30: The Leslie Sawhny Programme of Training for Democracy — a Tata-linked centre for civic and leadership education. | G30: Yes | J30: No | K30: leslie-sawhny-centre
A31: Liberal International | B31: founded 1947 | C31: International Network | D31: Classical Liberal | F31: The world federation of liberal political parties, founded in 1947. | G31: Yes | J31: Yes | K31: liberal-international
A32: Liberal Party of Sri Lanka | B32: founded 1987 | C32: Political Party | D32: Classical Liberal | F32: Sri Lanka's liberal party, founded in 1987 by Chanaka Amaratunga. | G32: No | J32: No | K32: liberal-party-of-sri-lanka
A33: Libertarian Publishers | C33: Publisher / Press | D33: Classical Liberal | E33: Libertarian | F33: Bombay imprint of R. B. Lotvala's libertarian circle, publisher of The Indian Libertarian. | G33: Yes | J33: No | K33: libertarian-publishers
A34: Libertarian Social Institute | C34: Academic Institution | D34: Classical Liberal | E34: Libertarian | F34: The Bombay institute endowed by R. B. Lotvala to spread libertarian and rationalist ideas; home of The Indian Libertarian. | G34: Yes | J34: No | K34: libertarian-social-institute
A35: Liberty Institute | B35: founded 1996 | C35: Think Tank | D35: Classical Liberal | F35: New Delhi free-market think tank founded in 1996 by Barun Mitra. | G35: Yes | J35: No | K35: liberty-institute
A36: Maharashtra Economic Development Council | C36: Think Tank | F36: Mumbai council promoting Maharashtra's economic development through research and business dialogue. | G36: Yes | J36: No | K36: maharashtra-economic-development-council
A37: Manaktalas | C37: Publisher / Press | F37: Bombay publishing house of the 1960s that issued several liberal titles in this archive. | G37: Yes | J37: No | K37: manaktalas
A38: Mont Pelerin Society | B38: founded 1947 | C38: International Network | D38: Classical Liberal | F38: The international society of classical-liberal scholars convened by Hayek at Mont Pèlerin in 1947; B. R. Shenoy was its first Indian member. | G38: Yes | J38: Yes | K38: mont-pelerin-society
A39: NCAER | B39: founded 1956 | C39: Academic Institution | F39: The National Council of Applied Economic Research, New Delhi — India's oldest independent economic policy research institute, founded in 1956. | G39: Yes | J39: Yes | K39: ncaer
A40: Observer Research Foundation | B40: founded 1990 | C40: Think Tank | F40: New Delhi policy think tank founded in 1990. | G40: Yes | J40: Yes | K40: observer-research-foundation
...
